Workbook

Sheet Calculation
A1: FREELANCER SHEET
A2: COMPANY NAME | B2: DATE ASSIGNED | C2: TASK | D2: INCHARGE | E2: DUTY | F2: QTY | G2: COST FOR ONE WORK | H2: TOTAL COST(F*G) | I2: SUBMISSION DATE | J2: INCHARGE + BONUS | K2: INCHARGE + BONUS + WORK | L2: HOBO AMOUNT
A3: Sony Tyres | B3: 45456 | C3: Short video design | D3: Anu Shigha | E3: Anu Shigha | F3: 2 | G3: =IF(OR(A3="NIL", C3="NIL", D3="NIL", E3="NIL"), 0, INDEX($B$136:$F$152, MATCH(E3, $A$136:$A$152, 0), MATCH(C3, $B$135:$F$135, 0))) -> 312.5 | H3: =G3*F3 -> 625 | I3: 45486 | J3: =IF(OR(A3="NIL", C3="NIL", D3="NIL", E3="NIL"), 0, IFERROR( (INDEX($B$136:$G$136, 1, MATCH(C3, $B$135:$I$135, 0)) - G3) * F3 + INDEX($G$138:$I$141, MATCH(D3, $A$138:$A$141, 0), MATCH(C3, $B$135:$F$135, 0)) * F3, 0) ) -> 172 | K3: =IFERROR(IFS(D3=E3,H3+J3,D3<>E3,J3),0) -> 797 | L3: =SUM(VLOOKUP(A3,$A$165:$C$178,2,False)*25%,VLOOKUP(A3,$A$165:$C$178,3,False)*25%) -> 1875
B4: 45489 | C4: Short video design | D4: Anu Shigha | E4: Anu Shigha | F4: 3 | G4: =IF(OR(A4="NIL", C4="NIL", D4="NIL", E4="NIL"), 0, INDEX($B$136:$F$152, MATCH(E4, $A$136:$A$152, 0), MATCH(C4, $B$135:$F$135, 0))) -> 312.5 | H4: =G4*F4 -> 937.5 | I4: 45447 | J4: =IF(OR(A4="NIL", C4="NIL", D4="NIL", E4="NIL"), 0, IFERROR( (INDEX($B$136:$G$136, 1, MATCH(C4, $B$135:$I$135, 0)) - G4) * F4 + INDEX($G$138:$I$141, MATCH(D4, $A$138:$A$141, 0), MATCH(C4, $B$135:$F$135, 0)) * F4, 0) ) -> 258 | K4: =IFERROR(IFS(D4=E4,H4+J4,D4<>E4,J4),0) -> 1195.5
B5: 45455 | C5: Poster Design | D5: Anu Shigha | E5: Ram | F5: 1 | G5: =IF(OR(A5="NIL", C5="NIL", D5="NIL", E5="NIL"), 0, INDEX($B$136:$F$152, MATCH(E5, $A$136:$A$152, 0), MATCH(C5, $B$135:$F$135, 0))) -> 100 | H5: =G5*F5 -> 100 | I5: 45455 | J5: =IF(OR(A5="NIL", C5="NIL", D5="NIL", E5="NIL"), 0, IFERROR( (INDEX($B$136:$G$136, 1, MATCH(C5, $B$135:$I$135, 0)) - G5) * F5 + INDEX($G$138:$I$141, MATCH(D5, $A$138:$A$141, 0), MATCH(C5, $B$135:$F$135, 0)) * F5, 0) ) -> 0 | K5: =IFERROR(IFS(D5=E5,H5+J5,D5<>E5,J5),0) -> 0
B6: 45448 | C6: Short video design | D6: Nebil Divay | E6: Nebil Divay | F6: 2 | G6: =IF(OR(A6="NIL", C6="NIL", D6="NIL", E6="NIL"), 0, INDEX($B$136:$F$152, MATCH(E6, $A$136:$A$152, 0), MATCH(C6, $B$135:$F$135, 0))) -> 312.5 | H6: =G6*F6 -> 625 | I6: 45455 | J6: {=IF(OR(A6="NIL", C6="NIL", D6="NIL", E6="NIL"), 0, IFERROR( (INDEX($B$136:$F$136, 1, MATCH(C6, $B$135:$F$135, 0)) - G6) * F6 + INDEX($G$138:$I$141, MATCH(D6, $A$138:$A$141, 0), MATCH(C6, $B$135:$F$135, 0)) * F6, 0) )} -> 172 | K6: =IFERROR(IFS(D6=E6,H6+J6,D6<>E6,J6),0) -> 797
B7: 45458 | C7: Short video design | D7: Vishnu Kalpamangalam | E7: Dyan | F7: 10 | G7: =IF(OR(A7="NIL", C7="NIL", D7="NIL", E7="NIL"), 0, INDEX($B$136:$F$152, MATCH(E7, $A$136:$A$152, 0), MATCH(C7, $B$135:$F$135, 0))) -> 200 | H7: =G7*F7 -> 2000 | I7: 45473 | J7: =IFERROR(IFS(A7="NIL",0,C7="NIL",0,D7="NIL",0,E7="NIL",0,AND(D7=$A$138,C7=$F$135),SUM(($F$136-G7)*F7,$G$138*F7), AND(D7=$A$138,C7=$B$135),SUM(($B$136-G7)*F7,$H$138*F7),AND(D7=$A$138,C7=$C$135),SUM(($C$136-G7)*F7,$I$138*F7),AND(D7=$A$139,C7=$F$135),SUM(($F$136-G7)*F7,$G$139*F7), AND(D7=$A$139,C7=$B$135),SUM(($B$136-G7)*F7,$H$139*F7),AND(D7=$A$139,C7=$C$135),SUM(($C$136-G7)*F7,$I$139*F7),AND(D7=$A$140,C7=$F$135),SUM(($F$136-G7)*F7,$G$140*F7), AND(D7=$A$140,C7=$B$135),SUM(($B$136-G7)*F7,$H$140*F7),AND(D7=$A$140,C7=$C$135),SUM(($C$136-G7)*F7,$I$140*F7),AND(D7=$A$141,C7=$F$135),SUM(($F$136-G7)*F7,$G$141*F7), AND(D7=$A$141,C7=$B$135),SUM(($B$136-G7)*F7,$H$141*F7),AND(D7=$A$141,C7=$C$135),SUM(($C$136-G7)*F7,$I$141*F7)),"") -> 2687.5 | K7: =IFERROR(IFS(D7=E7,H7+J7,D7<>E7,J7),0) -> 2687.5
B8: 45457 | C8: Short video design | D8: Anu Shigha | E8: Anuba | F8: 2 | G8: =IF(OR(A8="NIL", C8="NIL", D8="NIL", E8="NIL"), 0, INDEX($B$136:$F$152, MATCH(E8, $A$136:$A$152, 0), MATCH(C8, $B$135:$F$135, 0))) -> 35 | H8: =G8*F8 -> 70 | I8: 45447 | J8: =IFERROR(IFS(A8="NIL",0,C8="NIL",0,D8="NIL",0,E8="NIL",0,AND(D8=$A$138,C8=$F$135),SUM(($F$136-G8)*F8,$G$138*F8), AND(D8=$A$138,C8=$B$135),SUM(($B$136-G8)*F8,$H$138*F8),AND(D8=$A$138,C8=$C$135),SUM(($C$136-G8)*F8,$I$138*F8),AND(D8=$A$139,C8=$F$135),SUM(($F$136-G8)*F8,$G$139*F8), AND(D8=$A$139,C8=$B$135),SUM(($B$136-G8)*F8,$H$139*F8),AND(D8=$A$139,C8=$C$135),SUM(($C$136-G8)*F8,$I$139*F8),AND(D8=$A$140,C8=$F$135),SUM(($F$136-G8)*F8,$G$140*F8), AND(D8=$A$140,C8=$B$135),SUM(($B$136-G8)*F8,$H$140*F8),AND(D8=$A$140,C8=$C$135),SUM(($C$136-G8)*F8,$I$140*F8),AND(D8=$A$141,C8=$F$135),SUM(($F$136-G8)*F8,$G$141*F8), AND(D8=$A$141,C8=$B$135),SUM(($B$136-G8)*F8,$H$141*F8),AND(D8=$A$141,C8=$C$135),SUM(($C$136-G8)*F8,$I$141*F8)),"") -> 867.5 | K8: =IFERROR(IFS(D8=E8,H8+J8,D8<>E8,J8),0) -> 867.5
B9: 45471 | C9: Short video design | D9: Vishnu Kalpamangalam | E9: Dyan | F9: 2 | G9: =IF(OR(A9="NIL", C9="NIL", D9="NIL", E9="NIL"), 0, INDEX($B$136:$F$152, MATCH(E9, $A$136:$A$152, 0), MATCH(C9, $B$135:$F$135, 0))) -> 200 | H9: =G9*F9 -> 400 | I9: 45447 | J9: =IFERROR(IFS(A9="NIL",0,C9="NIL",0,D9="NIL",0,E9="NIL",0,AND(D9=$A$138,C9=$F$135),SUM(($F$136-G9)*F9,$G$138*F9), AND(D9=$A$138,C9=$B$135),SUM(($B$136-G9)*F9,$H$138*F9),AND(D9=$A$138,C9=$C$135),SUM(($C$136-G9)*F9,$I$138*F9),AND(D9=$A$139,C9=$F$135),SUM(($F$136-G9)*F9,$G$139*F9), AND(D9=$A$139,C9=$B$135),SUM(($B$136-G9)*F9,$H$139*F9),AND(D9=$A$139,C9=$C$135),SUM(($C$136-G9)*F9,$I$139*F9),AND(D9=$A$140,C9=$F$135),SUM(($F$136-G9)*F9,$G$140*F9), AND(D9=$A$140,C9=$B$135),SUM(($B$136-G9)*F9,$H$140*F9),AND(D9=$A$140,C9=$C$135),SUM(($C$136-G9)*F9,$I$140*F9),AND(D9=$A$141,C9=$F$135),SUM(($F$136-G9)*F9,$G$141*F9), AND(D9=$A$141,C9=$B$135),SUM(($B$136-G9)*F9,$H$141*F9),AND(D9=$A$141,C9=$C$135),SUM(($C$136-G9)*F9,$I$141*F9)),"") -> 537.5 | K9: =IFERROR(IFS(D9=E9,H9+J9,D9<>E9,J9),0) -> 537.5
B10: 45464 | C10: Short video design | D10: Siddharth Mohan | E10: Siddharth Mohan | F10: 2 | G10: =IF(OR(A10="NIL", C10="NIL", D10="NIL", E10="NIL"), 0, INDEX($B$136:$F$152, MATCH(E10, $A$136:$A$152, 0), MATCH(C10, $B$135:$F$135, 0))) -> 312.5 | H10: =G10*F10 -> 625 | J10: =IFERROR(IFS(A10="NIL",0,C10="NIL",0,D10="NIL",0,E10="NIL",0,AND(D10=$A$138,C10=$F$135),SUM(($F$136-G10)*F10,$G$138*F10), AND(D10=$A$138,C10=$B$135),SUM(($B$136-G10)*F10,$H$138*F10),AND(D10=$A$138,C10=$C$135),SUM(($C$136-G10)*F10,$I$138*F10),AND(D10=$A$139,C10=$F$135),SUM(($F$136-G10)*F10,$G$139*F10), AND(D10=$A$139,C10=$B$135),SUM(($B$136-G10)*F10,$H$139*F10),AND(D10=$A$139,C10=$C$135),SUM(($C$136-G10)*F10,$I$139*F10),AND(D10=$A$140,C10=$F$135),SUM(($F$136-G10)*F10,$G$140*F10), AND(D10=$A$140,C10=$B$135),SUM(($B$136-G10)*F10,$H$140*F10),AND(D10=$A$140,C10=$C$135),SUM(($C$136-G10)*F10,$I$140*F10),AND(D10=$A$141,C10=$F$135),SUM(($F$136-G10)*F10,$G$141*F10), AND(D10=$A$141,C10=$B$135),SUM(($B$136-G10)*F10,$H$141*F10),AND(D10=$A$141,C10=$C$135),SUM(($C$136-G10)*F10,$I$141*F10)),"") -> 312.5 | K10: =IFERROR(IFS(D10=E10,H10+J10,D10<>E10,J10),0) -> 937.5
B11: 45498 | C11: Poster Design | D11: Nebil Divay | E11: Sachu | F11: 4 | G11: =IF(OR(A11="NIL", C11="NIL", D11="NIL", E11="NIL"), 0, INDEX($B$136:$F$152, MATCH(E11, $A$136:$A$152, 0), MATCH(C11, $B$135:$F$135, 0))) -> 44 | H11: =G11*F11 -> 176 | I11: 45974 | J11: =IFERROR(IFS(A11="NIL",0,C11="NIL",0,D11="NIL",0,E11="NIL",0,AND(D11=$A$138,C11=$F$135),SUM(($F$136-G11)*F11,$G$138*F11), AND(D11=$A$138,C11=$B$135),SUM(($B$136-G11)*F11,$H$138*F11),AND(D11=$A$138,C11=$C$135),SUM(($C$136-G11)*F11,$I$138*F11),AND(D11=$A$139,C11=$F$135),SUM(($F$136-G11)*F11,$G$139*F11), AND(D11=$A$139,C11=$B$135),SUM(($B$136-G11)*F11,$H$139*F11),AND(D11=$A$139,C11=$C$135),SUM(($C$136-G11)*F11,$I$139*F11),AND(D11=$A$140,C11=$F$135),SUM(($F$136-G11)*F11,$G$140*F11), AND(D11=$A$140,C11=$B$135),SUM(($B$136-G11)*F11,$H$140*F11),AND(D11=$A$140,C11=$C$135),SUM(($C$136-G11)*F11,$I$140*F11),AND(D11=$A$141,C11=$F$135),SUM(($F$136-G11)*F11,$G$141*F11), AND(D11=$A$141,C11=$B$135),SUM(($B$136-G11)*F11,$H$141*F11),AND(D11=$A$141,C11=$C$135),SUM(($C$136-G11)*F11,$I$141*F11)),"") -> 728 | K11: =IFERROR(IFS(D11=E11,H11+J11,D11<>E11,J11),0) -> 728
B12: 45463 | C12: Poster Design | D12: Anu Shigha | E12: Achu | F12: 5 | G12: =IF(OR(A12="NIL", C12="NIL", D12="NIL", E12="NIL"), 0, INDEX($B$136:$F$152, MATCH(E12, $A$136:$A$152, 0), MATCH(C12, $B$135:$F$135, 0))) -> 44 | H12: =G12*F12 -> 220 | J12: =IFERROR(IFS(A12="NIL",0,C12="NIL",0,D12="NIL",0,E12="NIL",0,AND(D12=$A$138,C12=$F$135),SUM(($F$136-G12)*F12,$G$138*F12), AND(D12=$A$138,C12=$B$135),SUM(($B$136-G12)*F12,$H$138*F12),AND(D12=$A$138,C12=$C$135),SUM(($C$136-G12)*F12,$I$138*F12),AND(D12=$A$139,C12=$F$135),SUM(($F$136-G12)*F12,$G$139*F12), AND(D12=$A$139,C12=$B$135),SUM(($B$136-G12)*F12,$H$139*F12),AND(D12=$A$139,C12=$C$135),SUM(($C$136-G12)*F12,$I$139*F12),AND(D12=$A$140,C12=$F$135),SUM(($F$136-G12)*F12,$G$140*F12), AND(D12=$A$140,C12=$B$135),SUM(($B$136-G12)*F12,$H$140*F12),AND(D12=$A$140,C12=$C$135),SUM(($C$136-G12)*F12,$I$140*F12),AND(D12=$A$141,C12=$F$135),SUM(($F$136-G12)*F12,$G$141*F12), AND(D12=$A$141,C12=$B$135),SUM(($B$136-G12)*F12,$H$141*F12),AND(D12=$A$141,C12=$C$135),SUM(($C$136-G12)*F12,$I$141*F12)),"") -> 910 | K12: =IFERROR(IFS(D12=E12,H12+J12,D12<>E12,J12),0) -> 910
B13: 45470 | C13: Content for Poster | D13: Anu Shigha | E13: Rehan | F13: 2 | G13: =IF(OR(A13="NIL", C13="NIL", D13="NIL", E13="NIL"), 0, INDEX($B$136:$F$152, MATCH(E13, $A$136:$A$152, 0), MATCH(C13, $B$135:$F$135, 0))) -> 22 | H13: =G13*F13 -> 44 | I13: 45987 | J13: =IFERROR(IFS(A13="NIL",0,C13="NIL",0,D13="NIL",0,E13="NIL",0,AND(D13=$A$138,C13=$F$135),SUM(($F$136-G13)*F13,$G$138*F13), AND(D13=$A$138,C13=$B$135),SUM(($B$136-G13)*F13,$H$138*F13),AND(D13=$A$138,C13=$C$135),SUM(($C$136-G13)*F13,$I$138*F13),AND(D13=$A$139,C13=$F$135),SUM(($F$136-G13)*F13,$G$139*F13), AND(D13=$A$139,C13=$B$135),SUM(($B$136-G13)*F13,$H$139*F13),AND(D13=$A$139,C13=$C$135),SUM(($C$136-G13)*F13,$I$139*F13),AND(D13=$A$140,C13=$F$135),SUM(($F$136-G13)*F13,$G$140*F13), AND(D13=$A$140,C13=$B$135),SUM(($B$136-G13)*F13,$H$140*F13),AND(D13=$A$140,C13=$C$135),SUM(($C$136-G13)*F13,$I$140*F13),AND(D13=$A$141,C13=$F$135),SUM(($F$136-G13)*F13,$G$141*F13), AND(D13=$A$141,C13=$B$135),SUM(($B$136-G13)*F13,$H$141*F13),AND(D13=$A$141,C13=$C$135),SUM(($C$136-G13)*F13,$I$141*F13)),"") | K13: =IFERROR(IFS(D13=E13,H13+J13,D13<>E13,J13),0)
B14: 45532 | C14: Content for Poster | D14: Nebil Divay | E14: Sreeju | F14: 1 | G14: =IF(OR(A14="NIL", C14="NIL", D14="NIL", E14="NIL"), 0, INDEX($B$136:$F$152, MATCH(E14, $A$136:$A$152, 0), MATCH(C14, $B$135:$F$135, 0))) -> 44 | H14: =G14*F14 -> 44 | I14: 45979 | J14: =IFERROR(IFS(A14="NIL",0,C14="NIL",0,D14="NIL",0,E14="NIL",0,AND(D14=$A$138,C14=$F$135),SUM(($F$136-G14)*F14,$G$138*F14), AND(D14=$A$138,C14=$B$135),SUM(($B$136-G14)*F14,$H$138*F14),AND(D14=$A$138,C14=$C$135),SUM(($C$136-G14)*F14,$I$138*F14),AND(D14=$A$139,C14=$F$135),SUM(($F$136-G14)*F14,$G$139*F14), AND(D14=$A$139,C14=$B$135),SUM(($B$136-G14)*F14,$H$139*F14),AND(D14=$A$139,C14=$C$135),SUM(($C$136-G14)*F14,$I$139*F14),AND(D14=$A$140,C14=$F$135),SUM(($F$136-G14)*F14,$G$140*F14), AND(D14=$A$140,C14=$B$135),SUM(($B$136-G14)*F14,$H$140*F14),AND(D14=$A$140,C14=$C$135),SUM(($C$136-G14)*F14,$I$140*F14),AND(D14=$A$141,C14=$F$135),SUM(($F$136-G14)*F14,$G$141*F14), AND(D14=$A$141,C14=$B$135),SUM(($B$136-G14)*F14,$H$141*F14),AND(D14=$A$141,C14=$C$135),SUM(($C$136-G14)*F14,$I$141*F14)),"") | K14: =IFERROR(IFS(D14=E14,H14+J14,D14<>E14,J14),0)
B15: 45525 | C15: Poster Design | D15: NIL | E15: NIL | G15: =IF(OR(A15="NIL", C15="NIL", D15="NIL", E15="NIL"), 0, INDEX($B$136:$F$152, MATCH(E15, $A$136:$A$152, 0), MATCH(C15, $B$135:$F$135, 0))) -> 0 | H15: =G15*F15 -> 0 | J15: =IFERROR(IFS(A15="NIL",0,C15="NIL",0,D15="NIL",0,E15="NIL",0,AND(D15=$A$138,C15=$F$135),SUM(($F$136-G15)*F15,$G$138*F15), AND(D15=$A$138,C15=$B$135),SUM(($B$136-G15)*F15,$H$138*F15),AND(D15=$A$138,C15=$C$135),SUM(($C$136-G15)*F15,$I$138*F15),AND(D15=$A$139,C15=$F$135),SUM(($F$136-G15)*F15,$G$139*F15), AND(D15=$A$139,C15=$B$135),SUM(($B$136-G15)*F15,$H$139*F15),AND(D15=$A$139,C15=$C$135),SUM(($C$136-G15)*F15,$I$139*F15),AND(D15=$A$140,C15=$F$135),SUM(($F$136-G15)*F15,$G$140*F15), AND(D15=$A$140,C15=$B$135),SUM(($B$136-G15)*F15,$H$140*F15),AND(D15=$A$140,C15=$C$135),SUM(($C$136-G15)*F15,$I$140*F15),AND(D15=$A$141,C15=$F$135),SUM(($F$136-G15)*F15,$G$141*F15), AND(D15=$A$141,C15=$B$135),SUM(($B$136-G15)*F15,$H$141*F15),AND(D15=$A$141,C15=$C$135),SUM(($C$136-G15)*F15,$I$141*F15)),"") -> 0 | K15: =IFERROR(IFS(D15=E15,H15+J15,D15<>E15,J15),0) -> 0
A16: Alfah Cements | B16: 45471 | C16: Content for Poster | D16: Hobo | E16: Ram | F16: 2 | G16: =IF(OR(A16="NIL", C16="NIL", D16="NIL", E16="NIL"), 0, INDEX($B$136:$F$152, MATCH(E16, $A$136:$A$152, 0), MATCH(C16, $B$135:$F$135, 0))) -> 50 | H16: =G16*F16 -> 100 | I16: 45986 | J16: =IFERROR(IFS(A16="NIL",0,C16="NIL",0,D16="NIL",0,E16="NIL",0,AND(D16=$A$138,C16=$F$135),SUM(($F$136-G16)*F16,$G$138*F16), AND(D16=$A$138,C16=$B$135),SUM(($B$136-G16)*F16,$H$138*F16),AND(D16=$A$138,C16=$C$135),SUM(($C$136-G16)*F16,$I$138*F16),AND(D16=$A$139,C16=$F$135),SUM(($F$136-G16)*F16,$G$139*F16), AND(D16=$A$139,C16=$B$135),SUM(($B$136-G16)*F16,$H$139*F16),AND(D16=$A$139,C16=$C$135),SUM(($C$136-G16)*F16,$I$139*F16),AND(D16=$A$140,C16=$F$135),SUM(($F$136-G16)*F16,$G$140*F16), AND(D16=$A$140,C16=$B$135),SUM(($B$136-G16)*F16,$H$140*F16),AND(D16=$A$140,C16=$C$135),SUM(($C$136-G16)*F16,$I$140*F16),AND(D16=$A$141,C16=$F$135),SUM(($F$136-G16)*F16,$G$141*F16), AND(D16=$A$141,C16=$B$135),SUM(($B$136-G16)*F16,$H$141*F16),AND(D16=$A$141,C16=$C$135),SUM(($C$136-G16)*F16,$I$141*F16)),"") | K16: =IFERROR(IFS(D16=E16,H16+J16,D16<>E16,J16),0) | L16: =SUM(VLOOKUP(A16,$A$165:$C$178,2,False)*25%,VLOOKUP(A16,$A$165:$C$178,3,False)*25%) -> 1875
B17: 45455 | C17: NIL | D17: NIL | E17: NIL | G17: =IF(OR(A17="NIL", C17="NIL", D17="NIL", E17="NIL"), 0, INDEX($B$136:$F$152, MATCH(E17, $A$136:$A$152, 0), MATCH(C17, $B$135:$F$135, 0))) -> 0 | H17: =G17*F17 -> 0 | J17: =IFERROR(IFS(A17="NIL",0,C17="NIL",0,D17="NIL",0,E17="NIL",0,AND(D17=$A$138,C17=$F$135),SUM(($F$136-G17)*F17,$G$138*F17), AND(D17=$A$138,C17=$B$135),SUM(($B$136-G17)*F17,$H$138*F17),AND(D17=$A$138,C17=$C$135),SUM(($C$136-G17)*F17,$I$138*F17),AND(D17=$A$139,C17=$F$135),SUM(($F$136-G17)*F17,$G$139*F17), AND(D17=$A$139,C17=$B$135),SUM(($B$136-G17)*F17,$H$139*F17),AND(D17=$A$139,C17=$C$135),SUM(($C$136-G17)*F17,$I$139*F17),AND(D17=$A$140,C17=$F$135),SUM(($F$136-G17)*F17,$G$140*F17), AND(D17=$A$140,C17=$B$135),SUM(($B$136-G17)*F17,$H$140*F17),AND(D17=$A$140,C17=$C$135),SUM(($C$136-G17)*F17,$I$140*F17),AND(D17=$A$141,C17=$F$135),SUM(($F$136-G17)*F17,$G$141*F17), AND(D17=$A$141,C17=$B$135),SUM(($B$136-G17)*F17,$H$141*F17),AND(D17=$A$141,C17=$C$135),SUM(($C$136-G17)*F17,$I$141*F17)),"") -> 0 | K17: =IFERROR(IFS(D17=E17,H17+J17,D17<>E17,J17),0) -> 0
C18: NIL | D18: NIL | E18: NIL | G18: =IF(OR(A18="NIL", C18="NIL", D18="NIL", E18="NIL"), 0, INDEX($B$136:$F$152, MATCH(E18, $A$136:$A$152, 0), MATCH(C18, $B$135:$F$135, 0))) -> 0 | H18: =G18*F18 -> 0 | J18: =IFERROR(IFS(A18="NIL",0,C18="NIL",0,D18="NIL",0,E18="NIL",0,AND(D18=$A$138,C18=$F$135),SUM(($F$136-G18)*F18,$G$138*F18), AND(D18=$A$138,C18=$B$135),SUM(($B$136-G18)*F18,$H$138*F18),AND(D18=$A$138,C18=$C$135),SUM(($C$136-G18)*F18,$I$138*F18),AND(D18=$A$139,C18=$F$135),SUM(($F$136-G18)*F18,$G$139*F18), AND(D18=$A$139,C18=$B$135),SUM(($B$136-G18)*F18,$H$139*F18),AND(D18=$A$139,C18=$C$135),SUM(($C$136-G18)*F18,$I$139*F18),AND(D18=$A$140,C18=$F$135),SUM(($F$136-G18)*F18,$G$140*F18), AND(D18=$A$140,C18=$B$135),SUM(($B$136-G18)*F18,$H$140*F18),AND(D18=$A$140,C18=$C$135),SUM(($C$136-G18)*F18,$I$140*F18),AND(D18=$A$141,C18=$F$135),SUM(($F$136-G18)*F18,$G$141*F18), AND(D18=$A$141,C18=$B$135),SUM(($B$136-G18)*F18,$H$141*F18),AND(D18=$A$141,C18=$C$135),SUM(($C$136-G18)*F18,$I$141*F18)),"") -> 0 | K18: =IFERROR(IFS(D18=E18,H18+J18,D18<>E18,J18),0) -> 0
C19: NIL | D19: NIL | E19: NIL | G19: =IF(OR(A19="NIL", C19="NIL", D19="NIL", E19="NIL"), 0, INDEX($B$136:$F$152, MATCH(E19, $A$136:$A$152, 0), MATCH(C19, $B$135:$F$135, 0))) -> 0 | H19: =G19*F19 -> 0 | J19: =IFERROR(IFS(A19="NIL",0,C19="NIL",0,D19="NIL",0,E19="NIL",0,AND(D19=$A$138,C19=$F$135),SUM(($F$136-G19)*F19,$G$138*F19), AND(D19=$A$138,C19=$B$135),SUM(($B$136-G19)*F19,$H$138*F19),AND(D19=$A$138,C19=$C$135),SUM(($C$136-G19)*F19,$I$138*F19),AND(D19=$A$139,C19=$F$135),SUM(($F$136-G19)*F19,$G$139*F19), AND(D19=$A$139,C19=$B$135),SUM(($B$136-G19)*F19,$H$139*F19),AND(D19=$A$139,C19=$C$135),SUM(($C$136-G19)*F19,$I$139*F19),AND(D19=$A$140,C19=$F$135),SUM(($F$136-G19)*F19,$G$140*F19), AND(D19=$A$140,C19=$B$135),SUM(($B$136-G19)*F19,$H$140*F19),AND(D19=$A$140,C19=$C$135),SUM(($C$136-G19)*F19,$I$140*F19),AND(D19=$A$141,C19=$F$135),SUM(($F$136-G19)*F19,$G$141*F19), AND(D19=$A$141,C19=$B$135),SUM(($B$136-G19)*F19,$H$141*F19),AND(D19=$A$141,C19=$C$135),SUM(($C$136-G19)*F19,$I$141*F19)),"") -> 0 | K19: =IFERROR(IFS(D19=E19,H19+J19,D19<>E19,J19),0) -> 0
C20: NIL | D20: NIL | E20: NIL | G20: =IF(OR(A20="NIL", C20="NIL", D20="NIL", E20="NIL"), 0, INDEX($B$136:$F$152, MATCH(E20, $A$136:$A$152, 0), MATCH(C20, $B$135:$F$135, 0))) -> 0 | H20: =G20*F20 -> 0 | J20: =IFERROR(IFS(A20="NIL",0,C20="NIL",0,D20="NIL",0,E20="NIL",0,AND(D20=$A$138,C20=$F$135),SUM(($F$136-G20)*F20,$G$138*F20), AND(D20=$A$138,C20=$B$135),SUM(($B$136-G20)*F20,$H$138*F20),AND(D20=$A$138,C20=$C$135),SUM(($C$136-G20)*F20,$I$138*F20),AND(D20=$A$139,C20=$F$135),SUM(($F$136-G20)*F20,$G$139*F20), AND(D20=$A$139,C20=$B$135),SUM(($B$136-G20)*F20,$H$139*F20),AND(D20=$A$139,C20=$C$135),SUM(($C$136-G20)*F20,$I$139*F20),AND(D20=$A$140,C20=$F$135),SUM(($F$136-G20)*F20,$G$140*F20), AND(D20=$A$140,C20=$B$135),SUM(($B$136-G20)*F20,$H$140*F20),AND(D20=$A$140,C20=$C$135),SUM(($C$136-G20)*F20,$I$140*F20),AND(D20=$A$141,C20=$F$135),SUM(($F$136-G20)*F20,$G$141*F20), AND(D20=$A$141,C20=$B$135),SUM(($B$136-G20)*F20,$H$141*F20),AND(D20=$A$141,C20=$C$135),SUM(($C$136-G20)*F20,$I$141*F20)),"") -> 0 | K20: =IFERROR(IFS(D20=E20,H20+J20,D20<>E20,J20),0) -> 0
C21: NIL | D21: NIL | E21: NIL | F21: 2 | G21: =IF(OR(A21="NIL", C21="NIL", D21="NIL", E21="NIL"), 0, INDEX($B$136:$F$152, MATCH(E21, $A$136:$A$152, 0), MATCH(C21, $B$135:$F$135, 0))) -> 0 | H21: =G21*F21 -> 0 | J21: =IFERROR(IFS(A21="NIL",0,C21="NIL",0,D21="NIL",0,E21="NIL",0,AND(D21=$A$138,C21=$F$135),SUM(($F$136-G21)*F21,$G$138*F21), AND(D21=$A$138,C21=$B$135),SUM(($B$136-G21)*F21,$H$138*F21),AND(D21=$A$138,C21=$C$135),SUM(($C$136-G21)*F21,$I$138*F21),AND(D21=$A$139,C21=$F$135),SUM(($F$136-G21)*F21,$G$139*F21), AND(D21=$A$139,C21=$B$135),SUM(($B$136-G21)*F21,$H$139*F21),AND(D21=$A$139,C21=$C$135),SUM(($C$136-G21)*F21,$I$139*F21),AND(D21=$A$140,C21=$F$135),SUM(($F$136-G21)*F21,$G$140*F21), AND(D21=$A$140,C21=$B$135),SUM(($B$136-G21)*F21,$H$140*F21),AND(D21=$A$140,C21=$C$135),SUM(($C$136-G21)*F21,$I$140*F21),AND(D21=$A$141,C21=$F$135),SUM(($F$136-G21)*F21,$G$141*F21), AND(D21=$A$141,C21=$B$135),SUM(($B$136-G21)*F21,$H$141*F21),AND(D21=$A$141,C21=$C$135),SUM(($C$136-G21)*F21,$I$141*F21)),"") -> 0 | K21: =IFERROR(IFS(D21=E21,H21+J21,D21<>E21,J21),0) -> 0
C22: NIL | D22: NIL | E22: NIL | G22: =IF(OR(A22="NIL", C22="NIL", D22="NIL", E22="NIL"), 0, INDEX($B$136:$F$152, MATCH(E22, $A$136:$A$152, 0), MATCH(C22, $B$135:$F$135, 0))) -> 0 | H22: =G22*F22 -> 0 | J22: =IFERROR(IFS(A22="NIL",0,C22="NIL",0,D22="NIL",0,E22="NIL",0,AND(D22=$A$138,C22=$F$135),SUM(($F$136-G22)*F22,$G$138*F22), AND(D22=$A$138,C22=$B$135),SUM(($B$136-G22)*F22,$H$138*F22),AND(D22=$A$138,C22=$C$135),SUM(($C$136-G22)*F22,$I$138*F22),AND(D22=$A$139,C22=$F$135),SUM(($F$136-G22)*F22,$G$139*F22), AND(D22=$A$139,C22=$B$135),SUM(($B$136-G22)*F22,$H$139*F22),AND(D22=$A$139,C22=$C$135),SUM(($C$136-G22)*F22,$I$139*F22),AND(D22=$A$140,C22=$F$135),SUM(($F$136-G22)*F22,$G$140*F22), AND(D22=$A$140,C22=$B$135),SUM(($B$136-G22)*F22,$H$140*F22),AND(D22=$A$140,C22=$C$135),SUM(($C$136-G22)*F22,$I$140*F22),AND(D22=$A$141,C22=$F$135),SUM(($F$136-G22)*F22,$G$141*F22), AND(D22=$A$141,C22=$B$135),SUM(($B$136-G22)*F22,$H$141*F22),AND(D22=$A$141,C22=$C$135),SUM(($C$136-G22)*F22,$I$141*F22)),"") -> 0 | K22: =IFERROR(IFS(D22=E22,H22+J22,D22<>E22,J22),0) -> 0
C23: NIL | D23: NIL | E23: NIL | G23: =IF(OR(A23="NIL", C23="NIL", D23="NIL", E23="NIL"), 0, INDEX($B$136:$F$152, MATCH(E23, $A$136:$A$152, 0), MATCH(C23, $B$135:$F$135, 0))) -> 0 | H23: =G23*F23 -> 0 | J23: =IFERROR(IFS(A23="NIL",0,C23="NIL",0,D23="NIL",0,E23="NIL",0,AND(D23=$A$138,C23=$F$135),SUM(($F$136-G23)*F23,$G$138*F23), AND(D23=$A$138,C23=$B$135),SUM(($B$136-G23)*F23,$H$138*F23),AND(D23=$A$138,C23=$C$135),SUM(($C$136-G23)*F23,$I$138*F23),AND(D23=$A$139,C23=$F$135),SUM(($F$136-G23)*F23,$G$139*F23), AND(D23=$A$139,C23=$B$135),SUM(($B$136-G23)*F23,$H$139*F23),AND(D23=$A$139,C23=$C$135),SUM(($C$136-G23)*F23,$I$139*F23),AND(D23=$A$140,C23=$F$135),SUM(($F$136-G23)*F23,$G$140*F23), AND(D23=$A$140,C23=$B$135),SUM(($B$136-G23)*F23,$H$140*F23),AND(D23=$A$140,C23=$C$135),SUM(($C$136-G23)*F23,$I$140*F23),AND(D23=$A$141,C23=$F$135),SUM(($F$136-G23)*F23,$G$141*F23), AND(D23=$A$141,C23=$B$135),SUM(($B$136-G23)*F23,$H$141*F23),AND(D23=$A$141,C23=$C$135),SUM(($C$136-G23)*F23,$I$141*F23)),"") -> 0 | K23: =IFERROR(IFS(D23=E23,H23+J23,D23<>E23,J23),0) -> 0
C24: NIL | D24: NIL | E24: NIL | G24: =IF(OR(A24="NIL", C24="NIL", D24="NIL", E24="NIL"), 0, INDEX($B$136:$F$152, MATCH(E24, $A$136:$A$152, 0), MATCH(C24, $B$135:$F$135, 0))) -> 0 | H24: =G24*F24 -> 0 | J24: =IFERROR(IFS(A24="NIL",0,C24="NIL",0,D24="NIL",0,E24="NIL",0,AND(D24=$A$138,C24=$F$135),SUM(($F$136-G24)*F24,$G$138*F24), AND(D24=$A$138,C24=$B$135),SUM(($B$136-G24)*F24,$H$138*F24),AND(D24=$A$138,C24=$C$135),SUM(($C$136-G24)*F24,$I$138*F24),AND(D24=$A$139,C24=$F$135),SUM(($F$136-G24)*F24,$G$139*F24), AND(D24=$A$139,C24=$B$135),SUM(($B$136-G24)*F24,$H$139*F24),AND(D24=$A$139,C24=$C$135),SUM(($C$136-G24)*F24,$I$139*F24),AND(D24=$A$140,C24=$F$135),SUM(($F$136-G24)*F24,$G$140*F24), AND(D24=$A$140,C24=$B$135),SUM(($B$136-G24)*F24,$H$140*F24),AND(D24=$A$140,C24=$C$135),SUM(($C$136-G24)*F24,$I$140*F24),AND(D24=$A$141,C24=$F$135),SUM(($F$136-G24)*F24,$G$141*F24), AND(D24=$A$141,C24=$B$135),SUM(($B$136-G24)*F24,$H$141*F24),AND(D24=$A$141,C24=$C$135),SUM(($C$136-G24)*F24,$I$141*F24)),"") -> 0 | K24: =IFERROR(IFS(D24=E24,H24+J24,D24<>E24,J24),0) -> 0
C25: NIL | D25: NIL | E25: NIL | G25: =IF(OR(A25="NIL", C25="NIL", D25="NIL", E25="NIL"), 0, INDEX($B$136:$F$152, MATCH(E25, $A$136:$A$152, 0), MATCH(C25, $B$135:$F$135, 0))) -> 0 | H25: =G25*F25 -> 0 | J25: =IFERROR(IFS(A25="NIL",0,C25="NIL",0,D25="NIL",0,E25="NIL",0,AND(D25=$A$138,C25=$F$135),SUM(($F$136-G25)*F25,$G$138*F25), AND(D25=$A$138,C25=$B$135),SUM(($B$136-G25)*F25,$H$138*F25),AND(D25=$A$138,C25=$C$135),SUM(($C$136-G25)*F25,$I$138*F25),AND(D25=$A$139,C25=$F$135),SUM(($F$136-G25)*F25,$G$139*F25), AND(D25=$A$139,C25=$B$135),SUM(($B$136-G25)*F25,$H$139*F25),AND(D25=$A$139,C25=$C$135),SUM(($C$136-G25)*F25,$I$139*F25),AND(D25=$A$140,C25=$F$135),SUM(($F$136-G25)*F25,$G$140*F25), AND(D25=$A$140,C25=$B$135),SUM(($B$136-G25)*F25,$H$140*F25),AND(D25=$A$140,C25=$C$135),SUM(($C$136-G25)*F25,$I$140*F25),AND(D25=$A$141,C25=$F$135),SUM(($F$136-G25)*F25,$G$141*F25), AND(D25=$A$141,C25=$B$135),SUM(($B$136-G25)*F25,$H$141*F25),AND(D25=$A$141,C25=$C$135),SUM(($C$136-G25)*F25,$I$141*F25)),"") -> 0 | K25: =IFERROR(IFS(D25=E25,H25+J25,D25<>E25,J25),0) -> 0
C26: NIL | D26: NIL | E26: NIL | G26: =IF(OR(A26="NIL", C26="NIL", D26="NIL", E26="NIL"), 0, INDEX($B$136:$F$152, MATCH(E26, $A$136:$A$152, 0), MATCH(C26, $B$135:$F$135, 0))) -> 0 | H26: =G26*F26 -> 0 | J26: =IFERROR(IFS(A26="NIL",0,C26="NIL",0,D26="NIL",0,E26="NIL",0,AND(D26=$A$138,C26=$F$135),SUM(($F$136-G26)*F26,$G$138*F26), AND(D26=$A$138,C26=$B$135),SUM(($B$136-G26)*F26,$H$138*F26),AND(D26=$A$138,C26=$C$135),SUM(($C$136-G26)*F26,$I$138*F26),AND(D26=$A$139,C26=$F$135),SUM(($F$136-G26)*F26,$G$139*F26), AND(D26=$A$139,C26=$B$135),SUM(($B$136-G26)*F26,$H$139*F26),AND(D26=$A$139,C26=$C$135),SUM(($C$136-G26)*F26,$I$139*F26),AND(D26=$A$140,C26=$F$135),SUM(($F$136-G26)*F26,$G$140*F26), AND(D26=$A$140,C26=$B$135),SUM(($B$136-G26)*F26,$H$140*F26),AND(D26=$A$140,C26=$C$135),SUM(($C$136-G26)*F26,$I$140*F26),AND(D26=$A$141,C26=$F$135),SUM(($F$136-G26)*F26,$G$141*F26), AND(D26=$A$141,C26=$B$135),SUM(($B$136-G26)*F26,$H$141*F26),AND(D26=$A$141,C26=$C$135),SUM(($C$136-G26)*F26,$I$141*F26)),"") -> 0 | K26: =IFERROR(IFS(D26=E26,H26+J26,D26<>E26,J26),0) -> 0
C27: NIL | D27: NIL | E27: NIL | G27: =IF(OR(A27="NIL", C27="NIL", D27="NIL", E27="NIL"), 0, INDEX($B$136:$F$152, MATCH(E27, $A$136:$A$152, 0), MATCH(C27, $B$135:$F$135, 0))) -> 0 | H27: =G27*F27 -> 0 | J27: =IFERROR(IFS(A27="NIL",0,C27="NIL",0,D27="NIL",0,E27="NIL",0,AND(D27=$A$138,C27=$F$135),SUM(($F$136-G27)*F27,$G$138*F27), AND(D27=$A$138,C27=$B$135),SUM(($B$136-G27)*F27,$H$138*F27),AND(D27=$A$138,C27=$C$135),SUM(($C$136-G27)*F27,$I$138*F27),AND(D27=$A$139,C27=$F$135),SUM(($F$136-G27)*F27,$G$139*F27), AND(D27=$A$139,C27=$B$135),SUM(($B$136-G27)*F27,$H$139*F27),AND(D27=$A$139,C27=$C$135),SUM(($C$136-G27)*F27,$I$139*F27),AND(D27=$A$140,C27=$F$135),SUM(($F$136-G27)*F27,$G$140*F27), AND(D27=$A$140,C27=$B$135),SUM(($B$136-G27)*F27,$H$140*F27),AND(D27=$A$140,C27=$C$135),SUM(($C$136-G27)*F27,$I$140*F27),AND(D27=$A$141,C27=$F$135),SUM(($F$136-G27)*F27,$G$141*F27), AND(D27=$A$141,C27=$B$135),SUM(($B$136-G27)*F27,$H$141*F27),AND(D27=$A$141,C27=$C$135),SUM(($C$136-G27)*F27,$I$141*F27)),"") -> 0 | K27: =IFERROR(IFS(D27=E27,H27+J27,D27<>E27,J27),0) -> 0
C28: NIL | D28: NIL | E28: NIL | G28: =IF(OR(A28="NIL", C28="NIL", D28="NIL", E28="NIL"), 0, INDEX($B$136:$F$152, MATCH(E28, $A$136:$A$152, 0), MATCH(C28, $B$135:$F$135, 0))) -> 0 | H28: =G28*F28 -> 0 | J28: =IFERROR(IFS(A28="NIL",0,C28="NIL",0,D28="NIL",0,E28="NIL",0,AND(D28=$A$138,C28=$F$135),SUM(($F$136-G28)*F28,$G$138*F28), AND(D28=$A$138,C28=$B$135),SUM(($B$136-G28)*F28,$H$138*F28),AND(D28=$A$138,C28=$C$135),SUM(($C$136-G28)*F28,$I$138*F28),AND(D28=$A$139,C28=$F$135),SUM(($F$136-G28)*F28,$G$139*F28), AND(D28=$A$139,C28=$B$135),SUM(($B$136-G28)*F28,$H$139*F28),AND(D28=$A$139,C28=$C$135),SUM(($C$136-G28)*F28,$I$139*F28),AND(D28=$A$140,C28=$F$135),SUM(($F$136-G28)*F28,$G$140*F28), AND(D28=$A$140,C28=$B$135),SUM(($B$136-G28)*F28,$H$140*F28),AND(D28=$A$140,C28=$C$135),SUM(($C$136-G28)*F28,$I$140*F28),AND(D28=$A$141,C28=$F$135),SUM(($F$136-G28)*F28,$G$141*F28), AND(D28=$A$141,C28=$B$135),SUM(($B$136-G28)*F28,$H$141*F28),AND(D28=$A$141,C28=$C$135),SUM(($C$136-G28)*F28,$I$141*F28)),"") -> 0 | K28: =IFERROR(IFS(D28=E28,H28+J28,D28<>E28,J28),0) -> 0
A29: Prince Tyres | C29: Short video design | D29: Vishnu Kalpamangalam | E29: Ram | F29: 2 | G29: =IF(OR(A29="NIL", C29="NIL", D29="NIL", E29="NIL"), 0, INDEX($B$136:$F$152, MATCH(E29, $A$136:$A$152, 0), MATCH(C29, $B$135:$F$135, 0))) -> 200 | H29: =G29*F29 -> 400 | J29: =IFERROR(IFS(A29="NIL",0,C29="NIL",0,D29="NIL",0,E29="NIL",0,AND(D29=$A$138,C29=$F$135),SUM(($F$136-G29)*F29,$G$138*F29), AND(D29=$A$138,C29=$B$135),SUM(($B$136-G29)*F29,$H$138*F29),AND(D29=$A$138,C29=$C$135),SUM(($C$136-G29)*F29,$I$138*F29),AND(D29=$A$139,C29=$F$135),SUM(($F$136-G29)*F29,$G$139*F29), AND(D29=$A$139,C29=$B$135),SUM(($B$136-G29)*F29,$H$139*F29),AND(D29=$A$139,C29=$C$135),SUM(($C$136-G29)*F29,$I$139*F29),AND(D29=$A$140,C29=$F$135),SUM(($F$136-G29)*F29,$G$140*F29), AND(D29=$A$140,C29=$B$135),SUM(($B$136-G29)*F29,$H$140*F29),AND(D29=$A$140,C29=$C$135),SUM(($C$136-G29)*F29,$I$140*F29),AND(D29=$A$141,C29=$F$135),SUM(($F$136-G29)*F29,$G$141*F29), AND(D29=$A$141,C29=$B$135),SUM(($B$136-G29)*F29,$H$141*F29),AND(D29=$A$141,C29=$C$135),SUM(($C$136-G29)*F29,$I$141*F29)),"") -> 537.5 | K29: =IFERROR(IFS(D29=E29,H29+J29,D29<>E29,J29),0) -> 537.5 | L29: =SUM(VLOOKUP(A29,$A$165:$C$178,2,False)*25%,VLOOKUP(A29,$A$165:$C$178,3,False)*25%) -> 187.5
C30: NIL | D30: NIL | E30: NIL | G30: =IF(OR(A30="NIL", C30="NIL", D30="NIL", E30="NIL"), 0, INDEX($B$136:$F$152, MATCH(E30, $A$136:$A$152, 0), MATCH(C30, $B$135:$F$135, 0))) -> 0 | H30: =G30*F30 -> 0 | J30: =IFERROR(IFS(A30="NIL",0,C30="NIL",0,D30="NIL",0,E30="NIL",0,AND(D30=$A$138,C30=$F$135),SUM(($F$136-G30)*F30,$G$138*F30), AND(D30=$A$138,C30=$B$135),SUM(($B$136-G30)*F30,$H$138*F30),AND(D30=$A$138,C30=$C$135),SUM(($C$136-G30)*F30,$I$138*F30),AND(D30=$A$139,C30=$F$135),SUM(($F$136-G30)*F30,$G$139*F30), AND(D30=$A$139,C30=$B$135),SUM(($B$136-G30)*F30,$H$139*F30),AND(D30=$A$139,C30=$C$135),SUM(($C$136-G30)*F30,$I$139*F30),AND(D30=$A$140,C30=$F$135),SUM(($F$136-G30)*F30,$G$140*F30), AND(D30=$A$140,C30=$B$135),SUM(($B$136-G30)*F30,$H$140*F30),AND(D30=$A$140,C30=$C$135),SUM(($C$136-G30)*F30,$I$140*F30),AND(D30=$A$141,C30=$F$135),SUM(($F$136-G30)*F30,$G$141*F30), AND(D30=$A$141,C30=$B$135),SUM(($B$136-G30)*F30,$H$141*F30),AND(D30=$A$141,C30=$C$135),SUM(($C$136-G30)*F30,$I$141*F30)),"") -> 0 | K30: =IFERROR(IFS(D30=E30,H30+J30,D30<>E30,J30),0) -> 0
C31: NIL | D31: NIL | E31: NIL | G31: =IF(OR(A31="NIL", C31="NIL", D31="NIL", E31="NIL"), 0, INDEX($B$136:$F$152, MATCH(E31, $A$136:$A$152, 0), MATCH(C31, $B$135:$F$135, 0))) -> 0 | H31: =G31*F31 -> 0 | J31: =IFERROR(IFS(A31="NIL",0,C31="NIL",0,D31="NIL",0,E31="NIL",0,AND(D31=$A$138,C31=$F$135),SUM(($F$136-G31)*F31,$G$138*F31), AND(D31=$A$138,C31=$B$135),SUM(($B$136-G31)*F31,$H$138*F31),AND(D31=$A$138,C31=$C$135),SUM(($C$136-G31)*F31,$I$138*F31),AND(D31=$A$139,C31=$F$135),SUM(($F$136-G31)*F31,$G$139*F31), AND(D31=$A$139,C31=$B$135),SUM(($B$136-G31)*F31,$H$139*F31),AND(D31=$A$139,C31=$C$135),SUM(($C$136-G31)*F31,$I$139*F31),AND(D31=$A$140,C31=$F$135),SUM(($F$136-G31)*F31,$G$140*F31), AND(D31=$A$140,C31=$B$135),SUM(($B$136-G31)*F31,$H$140*F31),AND(D31=$A$140,C31=$C$135),SUM(($C$136-G31)*F31,$I$140*F31),AND(D31=$A$141,C31=$F$135),SUM(($F$136-G31)*F31,$G$141*F31), AND(D31=$A$141,C31=$B$135),SUM(($B$136-G31)*F31,$H$141*F31),AND(D31=$A$141,C31=$C$135),SUM(($C$136-G31)*F31,$I$141*F31)),"") -> 0 | K31: =IFERROR(IFS(D31=E31,H31+J31,D31<>E31,J31),0) -> 0
C32: NIL | D32: NIL | E32: NIL | G32: =IF(OR(A32="NIL", C32="NIL", D32="NIL", E32="NIL"), 0, INDEX($B$136:$F$152, MATCH(E32, $A$136:$A$152, 0), MATCH(C32, $B$135:$F$135, 0))) -> 0 | H32: =G32*F32 -> 0 | J32: =IFERROR(IFS(A32="NIL",0,C32="NIL",0,D32="NIL",0,E32="NIL",0,AND(D32=$A$138,C32=$F$135),SUM(($F$136-G32)*F32,$G$138*F32), AND(D32=$A$138,C32=$B$135),SUM(($B$136-G32)*F32,$H$138*F32),AND(D32=$A$138,C32=$C$135),SUM(($C$136-G32)*F32,$I$138*F32),AND(D32=$A$139,C32=$F$135),SUM(($F$136-G32)*F32,$G$139*F32), AND(D32=$A$139,C32=$B$135),SUM(($B$136-G32)*F32,$H$139*F32),AND(D32=$A$139,C32=$C$135),SUM(($C$136-G32)*F32,$I$139*F32),AND(D32=$A$140,C32=$F$135),SUM(($F$136-G32)*F32,$G$140*F32), AND(D32=$A$140,C32=$B$135),SUM(($B$136-G32)*F32,$H$140*F32),AND(D32=$A$140,C32=$C$135),SUM(($C$136-G32)*F32,$I$140*F32),AND(D32=$A$141,C32=$F$135),SUM(($F$136-G32)*F32,$G$141*F32), AND(D32=$A$141,C32=$B$135),SUM(($B$136-G32)*F32,$H$141*F32),AND(D32=$A$141,C32=$C$135),SUM(($C$136-G32)*F32,$I$141*F32)),"") -> 0 | K32: =IFERROR(IFS(D32=E32,H32+J32,D32<>E32,J32),0) -> 0
C33: NIL | D33: NIL | E33: NIL | G33: =IF(OR(A33="NIL", C33="NIL", D33="NIL", E33="NIL"), 0, INDEX($B$136:$F$152, MATCH(E33, $A$136:$A$152, 0), MATCH(C33, $B$135:$F$135, 0))) -> 0 | H33: =G33*F33 -> 0 | J33: =IFERROR(IFS(A33="NIL",0,C33="NIL",0,D33="NIL",0,E33="NIL",0,AND(D33=$A$138,C33=$F$135),SUM(($F$136-G33)*F33,$G$138*F33), AND(D33=$A$138,C33=$B$135),SUM(($B$136-G33)*F33,$H$138*F33),AND(D33=$A$138,C33=$C$135),SUM(($C$136-G33)*F33,$I$138*F33),AND(D33=$A$139,C33=$F$135),SUM(($F$136-G33)*F33,$G$139*F33), AND(D33=$A$139,C33=$B$135),SUM(($B$136-G33)*F33,$H$139*F33),AND(D33=$A$139,C33=$C$135),SUM(($C$136-G33)*F33,$I$139*F33),AND(D33=$A$140,C33=$F$135),SUM(($F$136-G33)*F33,$G$140*F33), AND(D33=$A$140,C33=$B$135),SUM(($B$136-G33)*F33,$H$140*F33),AND(D33=$A$140,C33=$C$135),SUM(($C$136-G33)*F33,$I$140*F33),AND(D33=$A$141,C33=$F$135),SUM(($F$136-G33)*F33,$G$141*F33), AND(D33=$A$141,C33=$B$135),SUM(($B$136-G33)*F33,$H$141*F33),AND(D33=$A$141,C33=$C$135),SUM(($C$136-G33)*F33,$I$141*F33)),"") -> 0 | K33: =IFERROR(IFS(D33=E33,H33+J33,D33<>E33,J33),0) -> 0
C34: NIL | D34: NIL | E34: NIL | G34: =IF(OR(A34="NIL", C34="NIL", D34="NIL", E34="NIL"), 0, INDEX($B$136:$F$152, MATCH(E34, $A$136:$A$152, 0), MATCH(C34, $B$135:$F$135, 0))) -> 0 | H34: =G34*F34 -> 0 | J34: =IFERROR(IFS(A34="NIL",0,C34="NIL",0,D34="NIL",0,E34="NIL",0,AND(D34=$A$138,C34=$F$135),SUM(($F$136-G34)*F34,$G$138*F34), AND(D34=$A$138,C34=$B$135),SUM(($B$136-G34)*F34,$H$138*F34),AND(D34=$A$138,C34=$C$135),SUM(($C$136-G34)*F34,$I$138*F34),AND(D34=$A$139,C34=$F$135),SUM(($F$136-G34)*F34,$G$139*F34), AND(D34=$A$139,C34=$B$135),SUM(($B$136-G34)*F34,$H$139*F34),AND(D34=$A$139,C34=$C$135),SUM(($C$136-G34)*F34,$I$139*F34),AND(D34=$A$140,C34=$F$135),SUM(($F$136-G34)*F34,$G$140*F34), AND(D34=$A$140,C34=$B$135),SUM(($B$136-G34)*F34,$H$140*F34),AND(D34=$A$140,C34=$C$135),SUM(($C$136-G34)*F34,$I$140*F34),AND(D34=$A$141,C34=$F$135),SUM(($F$136-G34)*F34,$G$141*F34), AND(D34=$A$141,C34=$B$135),SUM(($B$136-G34)*F34,$H$141*F34),AND(D34=$A$141,C34=$C$135),SUM(($C$136-G34)*F34,$I$141*F34)),"") -> 0 | K34: =IFERROR(IFS(D34=E34,H34+J34,D34<>E34,J34),0) -> 0
C35: NIL | D35: NIL | E35: NIL | G35: =IF(OR(A35="NIL", C35="NIL", D35="NIL", E35="NIL"), 0, INDEX($B$136:$F$152, MATCH(E35, $A$136:$A$152, 0), MATCH(C35, $B$135:$F$135, 0))) -> 0 | H35: =G35*F35 -> 0 | J35: =IFERROR(IFS(A35="NIL",0,C35="NIL",0,D35="NIL",0,E35="NIL",0,AND(D35=$A$138,C35=$F$135),SUM(($F$136-G35)*F35,$G$138*F35), AND(D35=$A$138,C35=$B$135),SUM(($B$136-G35)*F35,$H$138*F35),AND(D35=$A$138,C35=$C$135),SUM(($C$136-G35)*F35,$I$138*F35),AND(D35=$A$139,C35=$F$135),SUM(($F$136-G35)*F35,$G$139*F35), AND(D35=$A$139,C35=$B$135),SUM(($B$136-G35)*F35,$H$139*F35),AND(D35=$A$139,C35=$C$135),SUM(($C$136-G35)*F35,$I$139*F35),AND(D35=$A$140,C35=$F$135),SUM(($F$136-G35)*F35,$G$140*F35), AND(D35=$A$140,C35=$B$135),SUM(($B$136-G35)*F35,$H$140*F35),AND(D35=$A$140,C35=$C$135),SUM(($C$136-G35)*F35,$I$140*F35),AND(D35=$A$141,C35=$F$135),SUM(($F$136-G35)*F35,$G$141*F35), AND(D35=$A$141,C35=$B$135),SUM(($B$136-G35)*F35,$H$141*F35),AND(D35=$A$141,C35=$C$135),SUM(($C$136-G35)*F35,$I$141*F35)),"") -> 0 | K35: =IFERROR(IFS(D35=E35,H35+J35,D35<>E35,J35),0) -> 0
C36: NIL | D36: NIL | E36: NIL | G36: =IF(OR(A36="NIL", C36="NIL", D36="NIL", E36="NIL"), 0, INDEX($B$136:$F$152, MATCH(E36, $A$136:$A$152, 0), MATCH(C36, $B$135:$F$135, 0))) -> 0 | H36: =G36*F36 -> 0 | J36: =IFERROR(IFS(A36="NIL",0,C36="NIL",0,D36="NIL",0,E36="NIL",0,AND(D36=$A$138,C36=$F$135),SUM(($F$136-G36)*F36,$G$138*F36), AND(D36=$A$138,C36=$B$135),SUM(($B$136-G36)*F36,$H$138*F36),AND(D36=$A$138,C36=$C$135),SUM(($C$136-G36)*F36,$I$138*F36),AND(D36=$A$139,C36=$F$135),SUM(($F$136-G36)*F36,$G$139*F36), AND(D36=$A$139,C36=$B$135),SUM(($B$136-G36)*F36,$H$139*F36),AND(D36=$A$139,C36=$C$135),SUM(($C$136-G36)*F36,$I$139*F36),AND(D36=$A$140,C36=$F$135),SUM(($F$136-G36)*F36,$G$140*F36), AND(D36=$A$140,C36=$B$135),SUM(($B$136-G36)*F36,$H$140*F36),AND(D36=$A$140,C36=$C$135),SUM(($C$136-G36)*F36,$I$140*F36),AND(D36=$A$141,C36=$F$135),SUM(($F$136-G36)*F36,$G$141*F36), AND(D36=$A$141,C36=$B$135),SUM(($B$136-G36)*F36,$H$141*F36),AND(D36=$A$141,C36=$C$135),SUM(($C$136-G36)*F36,$I$141*F36)),"") -> 0 | K36: =IFERROR(IFS(D36=E36,H36+J36,D36<>E36,J36),0) -> 0
C37: NIL | D37: NIL | E37: NIL | G37: =IF(OR(A37="NIL", C37="NIL", D37="NIL", E37="NIL"), 0, INDEX($B$136:$F$152, MATCH(E37, $A$136:$A$152, 0), MATCH(C37, $B$135:$F$135, 0))) -> 0 | H37: =G37*F37 -> 0 | J37: =IFERROR(IFS(A37="NIL",0,C37="NIL",0,D37="NIL",0,E37="NIL",0,AND(D37=$A$138,C37=$F$135),SUM(($F$136-G37)*F37,$G$138*F37), AND(D37=$A$138,C37=$B$135),SUM(($B$136-G37)*F37,$H$138*F37),AND(D37=$A$138,C37=$C$135),SUM(($C$136-G37)*F37,$I$138*F37),AND(D37=$A$139,C37=$F$135),SUM(($F$136-G37)*F37,$G$139*F37), AND(D37=$A$139,C37=$B$135),SUM(($B$136-G37)*F37,$H$139*F37),AND(D37=$A$139,C37=$C$135),SUM(($C$136-G37)*F37,$I$139*F37),AND(D37=$A$140,C37=$F$135),SUM(($F$136-G37)*F37,$G$140*F37), AND(D37=$A$140,C37=$B$135),SUM(($B$136-G37)*F37,$H$140*F37),AND(D37=$A$140,C37=$C$135),SUM(($C$136-G37)*F37,$I$140*F37),AND(D37=$A$141,C37=$F$135),SUM(($F$136-G37)*F37,$G$141*F37), AND(D37=$A$141,C37=$B$135),SUM(($B$136-G37)*F37,$H$141*F37),AND(D37=$A$141,C37=$C$135),SUM(($C$136-G37)*F37,$I$141*F37)),"") -> 0 | K37: =IFERROR(IFS(D37=E37,H37+J37,D37<>E37,J37),0) -> 0
C38: NIL | D38: NIL | E38: NIL | G38: =IF(OR(A38="NIL", C38="NIL", D38="NIL", E38="NIL"), 0, INDEX($B$136:$F$152, MATCH(E38, $A$136:$A$152, 0), MATCH(C38, $B$135:$F$135, 0))) -> 0 | H38: =G38*F38 -> 0 | J38: =IFERROR(IFS(A38="NIL",0,C38="NIL",0,D38="NIL",0,E38="NIL",0,AND(D38=$A$138,C38=$F$135),SUM(($F$136-G38)*F38,$G$138*F38), AND(D38=$A$138,C38=$B$135),SUM(($B$136-G38)*F38,$H$138*F38),AND(D38=$A$138,C38=$C$135),SUM(($C$136-G38)*F38,$I$138*F38),AND(D38=$A$139,C38=$F$135),SUM(($F$136-G38)*F38,$G$139*F38), AND(D38=$A$139,C38=$B$135),SUM(($B$136-G38)*F38,$H$139*F38),AND(D38=$A$139,C38=$C$135),SUM(($C$136-G38)*F38,$I$139*F38),AND(D38=$A$140,C38=$F$135),SUM(($F$136-G38)*F38,$G$140*F38), AND(D38=$A$140,C38=$B$135),SUM(($B$136-G38)*F38,$H$140*F38),AND(D38=$A$140,C38=$C$135),SUM(($C$136-G38)*F38,$I$140*F38),AND(D38=$A$141,C38=$F$135),SUM(($F$136-G38)*F38,$G$141*F38), AND(D38=$A$141,C38=$B$135),SUM(($B$136-G38)*F38,$H$141*F38),AND(D38=$A$141,C38=$C$135),SUM(($C$136-G38)*F38,$I$141*F38)),"") -> 0 | K38: =IFERROR(IFS(D38=E38,H38+J38,D38<>E38,J38),0) -> 0
C39: NIL | D39: NIL | E39: NIL | G39: =IF(OR(A39="NIL", C39="NIL", D39="NIL", E39="NIL"), 0, INDEX($B$136:$F$152, MATCH(E39, $A$136:$A$152, 0), MATCH(C39, $B$135:$F$135, 0))) -> 0 | H39: =G39*F39 -> 0 | J39: =IFERROR(IFS(A39="NIL",0,C39="NIL",0,D39="NIL",0,E39="NIL",0,AND(D39=$A$138,C39=$F$135),SUM(($F$136-G39)*F39,$G$138*F39), AND(D39=$A$138,C39=$B$135),SUM(($B$136-G39)*F39,$H$138*F39),AND(D39=$A$138,C39=$C$135),SUM(($C$136-G39)*F39,$I$138*F39),AND(D39=$A$139,C39=$F$135),SUM(($F$136-G39)*F39,$G$139*F39), AND(D39=$A$139,C39=$B$135),SUM(($B$136-G39)*F39,$H$139*F39),AND(D39=$A$139,C39=$C$135),SUM(($C$136-G39)*F39,$I$139*F39),AND(D39=$A$140,C39=$F$135),SUM(($F$136-G39)*F39,$G$140*F39), AND(D39=$A$140,C39=$B$135),SUM(($B$136-G39)*F39,$H$140*F39),AND(D39=$A$140,C39=$C$135),SUM(($C$136-G39)*F39,$I$140*F39),AND(D39=$A$141,C39=$F$135),SUM(($F$136-G39)*F39,$G$141*F39), AND(D39=$A$141,C39=$B$135),SUM(($B$136-G39)*F39,$H$141*F39),AND(D39=$A$141,C39=$C$135),SUM(($C$136-G39)*F39,$I$141*F39)),"") -> 0 | K39: =IFERROR(IFS(D39=E39,H39+J39,D39<>E39,J39),0) -> 0
C40: NIL | D40: NIL | E40: NIL | G40: =IF(OR(A40="NIL", C40="NIL", D40="NIL", E40="NIL"), 0, INDEX($B$136:$F$152, MATCH(E40, $A$136:$A$152, 0), MATCH(C40, $B$135:$F$135, 0))) -> 0 | H40: =G40*F40 -> 0 | J40: =IFERROR(IFS(A40="NIL",0,C40="NIL",0,D40="NIL",0,E40="NIL",0,AND(D40=$A$138,C40=$F$135),SUM(($F$136-G40)*F40,$G$138*F40), AND(D40=$A$138,C40=$B$135),SUM(($B$136-G40)*F40,$H$138*F40),AND(D40=$A$138,C40=$C$135),SUM(($C$136-G40)*F40,$I$138*F40),AND(D40=$A$139,C40=$F$135),SUM(($F$136-G40)*F40,$G$139*F40), AND(D40=$A$139,C40=$B$135),SUM(($B$136-G40)*F40,$H$139*F40),AND(D40=$A$139,C40=$C$135),SUM(($C$136-G40)*F40,$I$139*F40),AND(D40=$A$140,C40=$F$135),SUM(($F$136-G40)*F40,$G$140*F40), AND(D40=$A$140,C40=$B$135),SUM(($B$136-G40)*F40,$H$140*F40),AND(D40=$A$140,C40=$C$135),SUM(($C$136-G40)*F40,$I$140*F40),AND(D40=$A$141,C40=$F$135),SUM(($F$136-G40)*F40,$G$141*F40), AND(D40=$A$141,C40=$B$135),SUM(($B$136-G40)*F40,$H$141*F40),AND(D40=$A$141,C40=$C$135),SUM(($C$136-G40)*F40,$I$141*F40)),"") -> 0 | K40: =IFERROR(IFS(D40=E40,H40+J40,D40<>E40,J40),0) -> 0
...

Sheet Ram
A1: RAM WORKSHEET
A2: Date Assigned | B2: Last Date | C2: Assigned by | D2: Company | E2: Task | F2: Qty | G2: Amount | H2: Total | I2: Grand Total
A3: =IF(Calculation!E3=Calculation!$A$142,Calculation!B3,"") | B3: =IF(Calculation!E3=Calculation!$A$142,Calculation!I3,"") | C3: =IF(Calculation!E3=Calculation!$A$142,Calculation!D3,"") | D3: =IF(Calculation!E3=Calculation!$A$142,Calculation!$A$3,"") | E3: =IF(Calculation!E3=Calculation!$A$142,Calculation!C3,"") | F3: =IF(Calculation!E3=Calculation!$A$142,Calculation!F3,"") | G3: =IF(Calculation!E3=Calculation!$A$142,Calculation!G3,"") | H3: =IF(Calculation!E3=Calculation!$A$142,Calculation!H3,"") | I3: =SUMIF(Calculation!E3:E125,Calculation!$A$142,Calculation!H3:H125) -> 700
A4: =IF(Calculation!E4=Calculation!$A$142,Calculation!B4,"") | B4: =IF(Calculation!E4=Calculation!$A$142,Calculation!I4,"") | C4: =IF(Calculation!E4=Calculation!$A$142,Calculation!D4,"") | D4: =IF(Calculation!E4=Calculation!$A$142,Calculation!$A$3,"") | E4: =IF(Calculation!E4=Calculation!$A$142,Calculation!C4,"") | F4: =IF(Calculation!E4=Calculation!$A$142,Calculation!F4,"") | G4: =IF(Calculation!E4=Calculation!$A$142,Calculation!G4,"") | H4: =IF(Calculation!E4=Calculation!$A$142,Calculation!H4,"")
A5: =IF(Calculation!E5=Calculation!$A$142,Calculation!B5,"") -> 45455 | B5: =IF(Calculation!E5=Calculation!$A$142,Calculation!I5,"") -> 45455 | C5: =IF(Calculation!E5=Calculation!$A$142,Calculation!D5,"") -> Anu Shigha | D5: =IF(Calculation!E5=Calculation!$A$142,Calculation!$A$3,"") -> Sony Tyres | E5: =IF(Calculation!E5=Calculation!$A$142,Calculation!C5,"") -> Poster Design | F5: =IF(Calculation!E5=Calculation!$A$142,Calculation!F5,"") -> 1 | G5: =IF(Calculation!E5=Calculation!$A$142,Calculation!G5,"") -> 100 | H5: =IF(Calculation!E5=Calculation!$A$142,Calculation!H5,"") -> 100
A6: =IF(Calculation!E6=Calculation!$A$142,Calculation!B6,"") | B6: =IF(Calculation!E6=Calculation!$A$142,Calculation!I6,"") | C6: =IF(Calculation!E6=Calculation!$A$142,Calculation!D6,"") | D6: =IF(Calculation!E6=Calculation!$A$142,Calculation!$A$3,"") | E6: =IF(Calculation!E6=Calculation!$A$142,Calculation!C6,"") | F6: =IF(Calculation!E6=Calculation!$A$142,Calculation!F6,"") | G6: =IF(Calculation!E6=Calculation!$A$142,Calculation!G6,"") | H6: =IF(Calculation!E6=Calculation!$A$142,Calculation!H6,"")
A7: =IF(Calculation!E7=Calculation!$A$142,Calculation!B7,"") | B7: =IF(Calculation!E7=Calculation!$A$142,Calculation!I7,"") | C7: =IF(Calculation!E7=Calculation!$A$142,Calculation!D7,"") | D7: =IF(Calculation!E7=Calculation!$A$142,Calculation!$A$3,"") | E7: =IF(Calculation!E7=Calculation!$A$142,Calculation!C7,"") | F7: =IF(Calculation!E7=Calculation!$A$142,Calculation!F7,"") | G7: =IF(Calculation!E7=Calculation!$A$142,Calculation!G7,"") | H7: =IF(Calculation!E7=Calculation!$A$142,Calculation!H7,"")
A8: =IF(Calculation!E8=Calculation!$A$142,Calculation!B8,"") | B8: =IF(Calculation!E8=Calculation!$A$142,Calculation!I8,"") | C8: =IF(Calculation!E8=Calculation!$A$142,Calculation!D8,"") | D8: =IF(Calculation!E8=Calculation!$A$142,Calculation!$A$3,"") | E8: =IF(Calculation!E8=Calculation!$A$142,Calculation!C8,"") | F8: =IF(Calculation!E8=Calculation!$A$142,Calculation!F8,"") | G8: =IF(Calculation!E8=Calculation!$A$142,Calculation!G8,"") | H8: =IF(Calculation!E8=Calculation!$A$142,Calculation!H8,"")
A9: =IF(Calculation!E9=Calculation!$A$142,Calculation!B9,"") | B9: =IF(Calculation!E9=Calculation!$A$142,Calculation!I9,"") | C9: =IF(Calculation!E9=Calculation!$A$142,Calculation!D9,"") | D9: =IF(Calculation!E9=Calculation!$A$142,Calculation!$A$3,"") | E9: =IF(Calculation!E9=Calculation!$A$142,Calculation!C9,"") | F9: =IF(Calculation!E9=Calculation!$A$142,Calculation!F9,"") | G9: =IF(Calculation!E9=Calculation!$A$142,Calculation!G9,"") | H9: =IF(Calculation!E9=Calculation!$A$142,Calculation!H9,"")
A10: =IF(Calculation!E10=Calculation!$A$142,Calculation!B10,"") | B10: =IF(Calculation!E10=Calculation!$A$142,Calculation!I10,"") | C10: =IF(Calculation!E10=Calculation!$A$142,Calculation!D10,"") | D10: =IF(Calculation!E10=Calculation!$A$142,Calculation!$A$3,"") | E10: =IF(Calculation!E10=Calculation!$A$142,Calculation!C10,"") | F10: =IF(Calculation!E10=Calculation!$A$142,Calculation!F10,"") | G10: =IF(Calculation!E10=Calculation!$A$142,Calculation!G10,"") | H10: =IF(Calculation!E10=Calculation!$A$142,Calculation!H10,"")
A11: =IF(Calculation!E11=Calculation!$A$142,Calculation!B11,"") | B11: =IF(Calculation!E11=Calculation!$A$142,Calculation!I11,"") | C11: =IF(Calculation!E11=Calculation!$A$142,Calculation!D11,"") | D11: =IF(Calculation!E11=Calculation!$A$142,Calculation!$A$3,"") | E11: =IF(Calculation!E11=Calculation!$A$142,Calculation!C11,"") | F11: =IF(Calculation!E11=Calculation!$A$142,Calculation!F11,"") | G11: =IF(Calculation!E11=Calculation!$A$142,Calculation!G11,"") | H11: =IF(Calculation!E11=Calculation!$A$142,Calculation!H11,"")
A12: =IF(Calculation!E12=Calculation!$A$142,Calculation!B12,"") | B12: =IF(Calculation!E12=Calculation!$A$142,Calculation!I12,"") | C12: =IF(Calculation!E12=Calculation!$A$142,Calculation!D12,"") | D12: =IF(Calculation!E12=Calculation!$A$142,Calculation!$A$3,"") | E12: =IF(Calculation!E12=Calculation!$A$142,Calculation!C12,"") | F12: =IF(Calculation!E12=Calculation!$A$142,Calculation!F12,"") | G12: =IF(Calculation!E12=Calculation!$A$142,Calculation!G12,"") | H12: =IF(Calculation!E12=Calculation!$A$142,Calculation!H12,"")
A13: =IF(Calculation!E13=Calculation!$A$142,Calculation!B13,"") | B13: =IF(Calculation!E13=Calculation!$A$142,Calculation!I13,"") | C13: =IF(Calculation!E13=Calculation!$A$142,Calculation!D13,"") | D13: =IF(Calculation!E13=Calculation!$A$142,Calculation!$A$3,"") | E13: =IF(Calculation!E13=Calculation!$A$142,Calculation!C13,"") | F13: =IF(Calculation!E13=Calculation!$A$142,Calculation!F13,"") | G13: =IF(Calculation!E13=Calculation!$A$142,Calculation!G13,"") | H13: =IF(Calculation!E13=Calculation!$A$142,Calculation!H13,"")
A14: =IF(Calculation!E14=Calculation!$A$142,Calculation!B14,"") | B14: =IF(Calculation!E14=Calculation!$A$142,Calculation!I14,"") | C14: =IF(Calculation!E14=Calculation!$A$142,Calculation!D14,"") | D14: =IF(Calculation!E14=Calculation!$A$142,Calculation!$A$3,"") | E14: =IF(Calculation!E14=Calculation!$A$142,Calculation!C14,"") | F14: =IF(Calculation!E14=Calculation!$A$142,Calculation!F14,"") | G14: =IF(Calculation!E14=Calculation!$A$142,Calculation!G14,"") | H14: =IF(Calculation!E14=Calculation!$A$142,Calculation!H14,"")
A15: =IF(Calculation!E15=Calculation!$A$142,Calculation!B15,"") | B15: =IF(Calculation!E15=Calculation!$A$142,Calculation!I15,"") | C15: =IF(Calculation!E15=Calculation!$A$142,Calculation!D15,"") | D15: =IF(Calculation!E15=Calculation!$A$142,Calculation!$A$3,"") | E15: =IF(Calculation!E15=Calculation!$A$142,Calculation!C15,"") | F15: =IF(Calculation!E15=Calculation!$A$142,Calculation!F15,"") | G15: =IF(Calculation!E15=Calculation!$A$142,Calculation!G15,"") | H15: =IF(Calculation!E15=Calculation!$A$142,Calculation!H15,"")
A16: =IF(Calculation!E16=Calculation!$A$142,Calculation!B16,"") -> 45471 | B16: =IF(Calculation!E16=Calculation!$A$142,Calculation!I16,"") -> 45986 | C16: =IF(Calculation!E16=Calculation!$A$142,Calculation!D16,"") -> Hobo | D16: =IF(Calculation!E16=Calculation!$A$142,Calculation!$A$16,"") -> Alfah Cements | E16: =IF(Calculation!E16=Calculation!$A$142,Calculation!C16,"") -> Content for Poster | F16: =IF(Calculation!E16=Calculation!$A$142,Calculation!F16,"") -> 2 | G16: =IF(Calculation!E16=Calculation!$A$142,Calculation!G16,"") -> 50 | H16: =IF(Calculation!E16=Calculation!$A$142,Calculation!H16,"") -> 100
A17: =IF(Calculation!E17=Calculation!$A$142,Calculation!B17,"") | B17: =IF(Calculation!E17=Calculation!$A$142,Calculation!I17,"") | C17: =IF(Calculation!E17=Calculation!$A$142,Calculation!D17,"") | D17: =IF(Calculation!E17=Calculation!$A$142,Calculation!$A$16,"") | E17: =IF(Calculation!E17=Calculation!$A$142,Calculation!C17,"") | F17: =IF(Calculation!E17=Calculation!$A$142,Calculation!F17,"") | G17: =IF(Calculation!E17=Calculation!$A$142,Calculation!G17,"") | H17: =IF(Calculation!E17=Calculation!$A$142,Calculation!H17,"")
A18: =IF(Calculation!E18=Calculation!$A$142,Calculation!B18,"") | B18: =IF(Calculation!E18=Calculation!$A$142,Calculation!I18,"") | C18: =IF(Calculation!E18=Calculation!$A$142,Calculation!D18,"") | D18: =IF(Calculation!E18=Calculation!$A$142,Calculation!$A$16,"") | E18: =IF(Calculation!E18=Calculation!$A$142,Calculation!C18,"") | F18: =IF(Calculation!E18=Calculation!$A$142,Calculation!F18,"") | G18: =IF(Calculation!E18=Calculation!$A$142,Calculation!G18,"") | H18: =IF(Calculation!E18=Calculation!$A$142,Calculation!H18,"")
A19: =IF(Calculation!E19=Calculation!$A$142,Calculation!B19,"") | B19: =IF(Calculation!E19=Calculation!$A$142,Calculation!I19,"") | C19: =IF(Calculation!E19=Calculation!$A$142,Calculation!D19,"") | D19: =IF(Calculation!E19=Calculation!$A$142,Calculation!$A$16,"") | E19: =IF(Calculation!E19=Calculation!$A$142,Calculation!C19,"") | F19: =IF(Calculation!E19=Calculation!$A$142,Calculation!F19,"") | G19: =IF(Calculation!E19=Calculation!$A$142,Calculation!G19,"") | H19: =IF(Calculation!E19=Calculation!$A$142,Calculation!H19,"")
A20: =IF(Calculation!E20=Calculation!$A$142,Calculation!B20,"") | B20: =IF(Calculation!E20=Calculation!$A$142,Calculation!I20,"") | C20: =IF(Calculation!E20=Calculation!$A$142,Calculation!D20,"") | D20: =IF(Calculation!E20=Calculation!$A$142,Calculation!$A$16,"") | E20: =IF(Calculation!E20=Calculation!$A$142,Calculation!C20,"") | F20: =IF(Calculation!E20=Calculation!$A$142,Calculation!F20,"") | G20: =IF(Calculation!E20=Calculation!$A$142,Calculation!G20,"") | H20: =IF(Calculation!E20=Calculation!$A$142,Calculation!H20,"")
A21: =IF(Calculation!E21=Calculation!$A$142,Calculation!B21,"") | B21: =IF(Calculation!E21=Calculation!$A$142,Calculation!I21,"") | C21: =IF(Calculation!E21=Calculation!$A$142,Calculation!D21,"") | D21: =IF(Calculation!E21=Calculation!$A$142,Calculation!$A$16,"") | E21: =IF(Calculation!E21=Calculation!$A$142,Calculation!C21,"") | F21: =IF(Calculation!E21=Calculation!$A$142,Calculation!F21,"") | G21: =IF(Calculation!E21=Calculation!$A$142,Calculation!G21,"") | H21: =IF(Calculation!E21=Calculation!$A$142,Calculation!H21,"")
A22: =IF(Calculation!E22=Calculation!$A$142,Calculation!B22,"") | B22: =IF(Calculation!E22=Calculation!$A$142,Calculation!I22,"") | C22: =IF(Calculation!E22=Calculation!$A$142,Calculation!D22,"") | D22: =IF(Calculation!E22=Calculation!$A$142,Calculation!$A$16,"") | E22: =IF(Calculation!E22=Calculation!$A$142,Calculation!C22,"") | F22: =IF(Calculation!E22=Calculation!$A$142,Calculation!F22,"") | G22: =IF(Calculation!E22=Calculation!$A$142,Calculation!G22,"") | H22: =IF(Calculation!E22=Calculation!$A$142,Calculation!H22,"")
A23: =IF(Calculation!E23=Calculation!$A$142,Calculation!B23,"") | B23: =IF(Calculation!E23=Calculation!$A$142,Calculation!I23,"") | C23: =IF(Calculation!E23=Calculation!$A$142,Calculation!D23,"") | D23: =IF(Calculation!E23=Calculation!$A$142,Calculation!$A$16,"") | E23: =IF(Calculation!E23=Calculation!$A$142,Calculation!C23,"") | F23: =IF(Calculation!E23=Calculation!$A$142,Calculation!F23,"") | G23: =IF(Calculation!E23=Calculation!$A$142,Calculation!G23,"") | H23: =IF(Calculation!E23=Calculation!$A$142,Calculation!H23,"")
A24: =IF(Calculation!E24=Calculation!$A$142,Calculation!B24,"") | B24: =IF(Calculation!E24=Calculation!$A$142,Calculation!I24,"") | C24: =IF(Calculation!E24=Calculation!$A$142,Calculation!D24,"") | D24: =IF(Calculation!E24=Calculation!$A$142,Calculation!$A$16,"") | E24: =IF(Calculation!E24=Calculation!$A$142,Calculation!C24,"") | F24: =IF(Calculation!E24=Calculation!$A$142,Calculation!F24,"") | G24: =IF(Calculation!E24=Calculation!$A$142,Calculation!G24,"") | H24: =IF(Calculation!E24=Calculation!$A$142,Calculation!H24,"")
A25: =IF(Calculation!E25=Calculation!$A$142,Calculation!B25,"") | B25: =IF(Calculation!E25=Calculation!$A$142,Calculation!I25,"") | C25: =IF(Calculation!E25=Calculation!$A$142,Calculation!D25,"") | D25: =IF(Calculation!E25=Calculation!$A$142,Calculation!$A$16,"") | E25: =IF(Calculation!E25=Calculation!$A$142,Calculation!C25,"") | F25: =IF(Calculation!E25=Calculation!$A$142,Calculation!F25,"") | G25: =IF(Calculation!E25=Calculation!$A$142,Calculation!G25,"") | H25: =IF(Calculation!E25=Calculation!$A$142,Calculation!H25,"")
A26: =IF(Calculation!E26=Calculation!$A$142,Calculation!B26,"") | B26: =IF(Calculation!E26=Calculation!$A$142,Calculation!I26,"") | C26: =IF(Calculation!E26=Calculation!$A$142,Calculation!D26,"") | D26: =IF(Calculation!E26=Calculation!$A$142,Calculation!$A$16,"") | E26: =IF(Calculation!E26=Calculation!$A$142,Calculation!C26,"") | F26: =IF(Calculation!E26=Calculation!$A$142,Calculation!F26,"") | G26: =IF(Calculation!E26=Calculation!$A$142,Calculation!G26,"") | H26: =IF(Calculation!E26=Calculation!$A$142,Calculation!H26,"")
A27: =IF(Calculation!E27=Calculation!$A$142,Calculation!B27,"") | B27: =IF(Calculation!E27=Calculation!$A$142,Calculation!I27,"") | C27: =IF(Calculation!E27=Calculation!$A$142,Calculation!D27,"") | D27: =IF(Calculation!E27=Calculation!$A$142,Calculation!$A$16,"") | E27: =IF(Calculation!E27=Calculation!$A$142,Calculation!C27,"") | F27: =IF(Calculation!E27=Calculation!$A$142,Calculation!F27,"") | G27: =IF(Calculation!E27=Calculation!$A$142,Calculation!G27,"") | H27: =IF(Calculation!E27=Calculation!$A$142,Calculation!H27,"")
A28: =IF(Calculation!E28=Calculation!$A$142,Calculation!B28,"") | B28: =IF(Calculation!E28=Calculation!$A$142,Calculation!I28,"") | C28: =IF(Calculation!E28=Calculation!$A$142,Calculation!D28,"") | D28: =IF(Calculation!E28=Calculation!$A$142,Calculation!$A$16,"") | E28: =IF(Calculation!E28=Calculation!$A$142,Calculation!C28,"") | F28: =IF(Calculation!E28=Calculation!$A$142,Calculation!F28,"") | G28: =IF(Calculation!E28=Calculation!$A$142,Calculation!G28,"") | H28: =IF(Calculation!E28=Calculation!$A$142,Calculation!H28,"")
A29: =IF(Calculation!E29=Calculation!$A$142,Calculation!B29,"") | B29: =IF(Calculation!E29=Calculation!$A$142,Calculation!I29,"") | C29: =IF(Calculation!E29=Calculation!$A$142,Calculation!D29,"") -> Vishnu Kalpamangalam | D29: =IF(Calculation!E29=Calculation!$A$142,Calculation!$A$29,"") -> Prince Tyres | E29: =IF(Calculation!E29=Calculation!$A$142,Calculation!C29,"") -> Short video design | F29: =IF(Calculation!E29=Calculation!$A$142,Calculation!F29,"") -> 2 | G29: =IF(Calculation!E29=Calculation!$A$142,Calculation!G29,"") -> 200 | H29: =IF(Calculation!E29=Calculation!$A$142,Calculation!H29,"") -> 400
A30: =IF(Calculation!E30=Calculation!$A$142,Calculation!B30,"") | B30: =IF(Calculation!E30=Calculation!$A$142,Calculation!I30,"") | C30: =IF(Calculation!E30=Calculation!$A$142,Calculation!D30,"") | D30: =IF(Calculation!E30=Calculation!$A$142,Calculation!$A$29,"") | E30: =IF(Calculation!E30=Calculation!$A$142,Calculation!C30,"") | F30: =IF(Calculation!E30=Calculation!$A$142,Calculation!F30,"") | G30: =IF(Calculation!E30=Calculation!$A$142,Calculation!G30,"") | H30: =IF(Calculation!E30=Calculation!$A$142,Calculation!H30,"")
A31: =IF(Calculation!E31=Calculation!$A$142,Calculation!B31,"") | B31: =IF(Calculation!E31=Calculation!$A$142,Calculation!I31,"") | C31: =IF(Calculation!E31=Calculation!$A$142,Calculation!D31,"") | D31: =IF(Calculation!E31=Calculation!$A$142,Calculation!$A$29,"") | E31: =IF(Calculation!E31=Calculation!$A$142,Calculation!C31,"") | F31: =IF(Calculation!E31=Calculation!$A$142,Calculation!F31,"") | G31: =IF(Calculation!E31=Calculation!$A$142,Calculation!G31,"") | H31: =IF(Calculation!E31=Calculation!$A$142,Calculation!H31,"")
A32: =IF(Calculation!E32=Calculation!$A$142,Calculation!B32,"") | B32: =IF(Calculation!E32=Calculation!$A$142,Calculation!I32,"") | C32: =IF(Calculation!E32=Calculation!$A$142,Calculation!D32,"") | D32: =IF(Calculation!E32=Calculation!$A$142,Calculation!$A$29,"") | E32: =IF(Calculation!E32=Calculation!$A$142,Calculation!C32,"") | F32: =IF(Calculation!E32=Calculation!$A$142,Calculation!F32,"") | G32: =IF(Calculation!E32=Calculation!$A$142,Calculation!G32,"") | H32: =IF(Calculation!E32=Calculation!$A$142,Calculation!H32,"")
A33: =IF(Calculation!E33=Calculation!$A$142,Calculation!B33,"") | B33: =IF(Calculation!E33=Calculation!$A$142,Calculation!I33,"") | C33: =IF(Calculation!E33=Calculation!$A$142,Calculation!D33,"") | D33: =IF(Calculation!E33=Calculation!$A$142,Calculation!$A$29,"") | E33: =IF(Calculation!E33=Calculation!$A$142,Calculation!C33,"") | F33: =IF(Calculation!E33=Calculation!$A$142,Calculation!F33,"") | G33: =IF(Calculation!E33=Calculation!$A$142,Calculation!G33,"") | H33: =IF(Calculation!E33=Calculation!$A$142,Calculation!H33,"")
A34: =IF(Calculation!E34=Calculation!$A$142,Calculation!B34,"") | B34: =IF(Calculation!E34=Calculation!$A$142,Calculation!I34,"") | C34: =IF(Calculation!E34=Calculation!$A$142,Calculation!D34,"") | D34: =IF(Calculation!E34=Calculation!$A$142,Calculation!$A$29,"") | E34: =IF(Calculation!E34=Calculation!$A$142,Calculation!C34,"") | F34: =IF(Calculation!E34=Calculation!$A$142,Calculation!F34,"") | G34: =IF(Calculation!E34=Calculation!$A$142,Calculation!G34,"") | H34: =IF(Calculation!E34=Calculation!$A$142,Calculation!H34,"")
A35: =IF(Calculation!E35=Calculation!$A$142,Calculation!B35,"") | B35: =IF(Calculation!E35=Calculation!$A$142,Calculation!I35,"") | C35: =IF(Calculation!E35=Calculation!$A$142,Calculation!D35,"") | D35: =IF(Calculation!E35=Calculation!$A$142,Calculation!$A$29,"") | E35: =IF(Calculation!E35=Calculation!$A$142,Calculation!C35,"") | F35: =IF(Calculation!E35=Calculation!$A$142,Calculation!F35,"") | G35: =IF(Calculation!E35=Calculation!$A$142,Calculation!G35,"") | H35: =IF(Calculation!E35=Calculation!$A$142,Calculation!H35,"")
A36: =IF(Calculation!E36=Calculation!$A$142,Calculation!B36,"") | B36: =IF(Calculation!E36=Calculation!$A$142,Calculation!I36,"") | C36: =IF(Calculation!E36=Calculation!$A$142,Calculation!D36,"") | D36: =IF(Calculation!E36=Calculation!$A$142,Calculation!$A$29,"") | E36: =IF(Calculation!E36=Calculation!$A$142,Calculation!C36,"") | F36: =IF(Calculation!E36=Calculation!$A$142,Calculation!F36,"") | G36: =IF(Calculation!E36=Calculation!$A$142,Calculation!G36,"") | H36: =IF(Calculation!E36=Calculation!$A$142,Calculation!H36,"")
A37: =IF(Calculation!E37=Calculation!$A$142,Calculation!B37,"") | B37: =IF(Calculation!E37=Calculation!$A$142,Calculation!I37,"") | C37: =IF(Calculation!E37=Calculation!$A$142,Calculation!D37,"") | D37: =IF(Calculation!E37=Calculation!$A$142,Calculation!$A$29,"") | E37: =IF(Calculation!E37=Calculation!$A$142,Calculation!C37,"") | F37: =IF(Calculation!E37=Calculation!$A$142,Calculation!F37,"") | G37: =IF(Calculation!E37=Calculation!$A$142,Calculation!G37,"") | H37: =IF(Calculation!E37=Calculation!$A$142,Calculation!H37,"")
A38: =IF(Calculation!E38=Calculation!$A$142,Calculation!B38,"") | B38: =IF(Calculation!E38=Calculation!$A$142,Calculation!I38,"") | C38: =IF(Calculation!E38=Calculation!$A$142,Calculation!D38,"") | D38: =IF(Calculation!E38=Calculation!$A$142,Calculation!$A$29,"") | E38: =IF(Calculation!E38=Calculation!$A$142,Calculation!C38,"") | F38: =IF(Calculation!E38=Calculation!$A$142,Calculation!F38,"") | G38: =IF(Calculation!E38=Calculation!$A$142,Calculation!G38,"") | H38: =IF(Calculation!E38=Calculation!$A$142,Calculation!H38,"")
A39: =IF(Calculation!E39=Calculation!$A$142,Calculation!B39,"") | B39: =IF(Calculation!E39=Calculation!$A$142,Calculation!I39,"") | C39: =IF(Calculation!E39=Calculation!$A$142,Calculation!D39,"") | D39: =IF(Calculation!E39=Calculation!$A$142,Calculation!$A$29,"") | E39: =IF(Calculation!E39=Calculation!$A$142,Calculation!C39,"") | F39: =IF(Calculation!E39=Calculation!$A$142,Calculation!F39,"") | G39: =IF(Calculation!E39=Calculation!$A$142,Calculation!G39,"") | H39: =IF(Calculation!E39=Calculation!$A$142,Calculation!H39,"")
A40: =IF(Calculation!E40=Calculation!$A$142,Calculation!B40,"") | B40: =IF(Calculation!E40=Calculation!$A$142,Calculation!I40,"") | C40: =IF(Calculation!E40=Calculation!$A$142,Calculation!D40,"") | D40: =IF(Calculation!E40=Calculation!$A$142,Calculation!$A$29,"") | E40: =IF(Calculation!E40=Calculation!$A$142,Calculation!C40,"") | F40: =IF(Calculation!E40=Calculation!$A$142,Calculation!F40,"") | G40: =IF(Calculation!E40=Calculation!$A$142,Calculation!G40,"") | H40: =IF(Calculation!E40=Calculation!$A$142,Calculation!H40,"")
...

Sheet Finan
A1: FINAN WORKSHEET
A2: Date Assigned | B2: Last Date | C2: Assigned by | D2: Company | E2: Task | F2: Qty | G2: Amount | H2: Total | I2: Grand Total
